[2022-08-25T21:58:29.965+0000] {taskinstance.py:1171} INFO - Dependencies all met for <TaskInstance: sensor2.partners_b manual__2022-08-25T21:58:28.586503+00:00 [queued]>
[2022-08-25T21:58:29.973+0000] {taskinstance.py:1171} INFO - Dependencies all met for <TaskInstance: sensor2.partners_b manual__2022-08-25T21:58:28.586503+00:00 [queued]>
[2022-08-25T21:58:29.975+0000] {taskinstance.py:1368} INFO - 
--------------------------------------------------------------------------------
[2022-08-25T21:58:29.976+0000] {taskinstance.py:1369} INFO - Starting attempt 1 of 1
[2022-08-25T21:58:29.977+0000] {taskinstance.py:1370} INFO - 
--------------------------------------------------------------------------------
[2022-08-25T21:58:29.986+0000] {taskinstance.py:1389} INFO - Executing <Task(FileSensor): partners_b> on 2022-08-25 21:58:28.586503+00:00
[2022-08-25T21:58:29.992+0000] {standard_task_runner.py:52} INFO - Started process 6996 to run task
[2022-08-25T21:58:29.995+0000] {standard_task_runner.py:79} INFO - Running: ['***', 'tasks', 'run', 'sensor2', 'partners_b', 'manual__2022-08-25T21:58:28.586503+00:00', '--job-id', '70', '--raw', '--subdir', 'DAGS_FOLDER/sensor2.py', '--cfg-path', '/tmp/tmp7sa5opnc', '--error-file', '/tmp/tmpf303pu2p']
[2022-08-25T21:58:29.997+0000] {standard_task_runner.py:80} INFO - Job 70: Subtask partners_b
[2022-08-25T21:58:30.048+0000] {task_command.py:371} INFO - Running <TaskInstance: sensor2.partners_b manual__2022-08-25T21:58:28.586503+00:00 [running]> on host 3ee5bfb2187e
[2022-08-25T21:58:30.114+0000] {taskinstance.py:1583} INFO - Exporting the following env vars:
AIRFLOW_CTX_DAG_OWNER=***
AIRFLOW_CTX_DAG_ID=sensor2
AIRFLOW_CTX_TASK_ID=partners_b
AIRFLOW_CTX_EXECUTION_DATE=2022-08-25T21:58:28.586503+00:00
AIRFLOW_CTX_TRY_NUMBER=1
AIRFLOW_CTX_DAG_RUN_ID=manual__2022-08-25T21:58:28.586503+00:00
[2022-08-25T21:58:30.144+0000] {taskinstance.py:1902} ERROR - Task failed with exception
Traceback (most recent call last):
  File "/home/airflow/.local/lib/python3.7/site-packages/airflow/sensors/base.py", line 277, in execute
    poke_return = self.poke(context)
  File "/home/airflow/.local/lib/python3.7/site-packages/airflow/sensors/filesystem.py", line 55, in poke
    hook = FSHook(self.fs_conn_id)
  File "/home/airflow/.local/lib/python3.7/site-packages/airflow/hooks/filesystem.py", line 38, in __init__
    conn = self.get_connection(conn_id)
  File "/home/airflow/.local/lib/python3.7/site-packages/airflow/hooks/base.py", line 67, in get_connection
    conn = Connection.get_connection_from_secrets(conn_id)
  File "/home/airflow/.local/lib/python3.7/site-packages/airflow/models/connection.py", line 430, in get_connection_from_secrets
    raise AirflowNotFoundException(f"The conn_id `{conn_id}` isn't defined")
airflow.exceptions.AirflowNotFoundException: The conn_id `conn_filesensor_b` isn't defined
[2022-08-25T21:58:30.149+0000] {taskinstance.py:1412} INFO - Marking task as FAILED. dag_id=sensor2, task_id=partners_b, execution_date=20220825T215828, start_date=20220825T215829, end_date=20220825T215830
[2022-08-25T21:58:30.157+0000] {standard_task_runner.py:97} ERROR - Failed to execute job 70 for task partners_b (The conn_id `conn_filesensor_b` isn't defined; 6996)
[2022-08-25T21:58:30.207+0000] {local_task_job.py:156} INFO - Task exited with return code 1
[2022-08-25T21:58:30.229+0000] {taskinstance.py:1744} ERROR - Error when executing on_failure_callback
Traceback (most recent call last):
  File "/home/airflow/.local/lib/python3.7/site-packages/airflow/models/taskinstance.py", line 1742, in _run_finished_callback
    task.on_failure_callback(context)
  File "/opt/airflow/dags/sensor2.py", line 20, in _failure_callback
    if isinstance(AirflowSensorTimeout):
TypeError: isinstance expected 2 arguments, got 1
[2022-08-25T21:58:30.253+0000] {local_task_job.py:279} INFO - 0 downstream tasks scheduled from follow-on schedule check
